[2023-12-19T11:25:26.535+0000] {taskinstance.py:1159} INFO - Dependencies all met for dep_context=non-requeueable deps ti=<TaskInstance: my_dag.sense_json_file scheduled__2023-01-11T00:00:00+00:00 [queued]>
[2023-12-19T11:25:27.696+0000] {taskinstance.py:1159} INFO - Dependencies all met for dep_context=requeueable deps ti=<TaskInstance: my_dag.sense_json_file scheduled__2023-01-11T00:00:00+00:00 [queued]>
[2023-12-19T11:25:27.704+0000] {taskinstance.py:1361} INFO - Starting attempt 1 of 2
[2023-12-19T11:25:32.632+0000] {taskinstance.py:1382} INFO - Executing <Task(PythonOperator): sense_json_file> on 2023-01-11 00:00:00+00:00
[2023-12-19T11:25:33.141+0000] {standard_task_runner.py:57} INFO - Started process 247 to run task
[2023-12-19T11:25:33.357+0000] {standard_task_runner.py:84} INFO - Running: ['***', 'tasks', 'run', 'my_dag', 'sense_json_file', 'scheduled__2023-01-11T00:00:00+00:00', '--job-id', '70', '--raw', '--subdir', 'DAGS_FOLDER/dag0001.py', '--cfg-path', '/tmp/tmp34z095im']
[2023-12-19T11:25:33.663+0000] {standard_task_runner.py:85} INFO - Job 70: Subtask sense_json_file
[2023-12-19T11:28:08.542+0000] {standard_task_runner.py:104} ERROR - Failed to execute job 70 for task sense_json_file ((psycopg2.OperationalError) connection to server at "postgres" (192.168.32.2), port 5432 failed: server closed the connection unexpectedly
	This probably means the server terminated abnormally
	before or while processing the request.

(Background on this error at: https://sqlalche.me/e/14/e3q8); 247)
[2023-12-19T11:28:10.422+0000] {local_task_job_runner.py:228} INFO - Task exited with return code 1
[2023-12-19T11:28:13.999+0000] {taskinstance.py:2778} INFO - 0 downstream tasks scheduled from follow-on schedule check
