[2023-12-22T22:15:27.656+0000] {taskinstance.py:1159} INFO - Dependencies all met for dep_context=non-requeueable deps ti=<TaskInstance: gcs_file_check_dag_2.sense_csv_file scheduled__2023-12-22T04:00:00+00:00 [queued]>
[2023-12-22T22:15:28.263+0000] {taskinstance.py:1159} INFO - Dependencies all met for dep_context=requeueable deps ti=<TaskInstance: gcs_file_check_dag_2.sense_csv_file scheduled__2023-12-22T04:00:00+00:00 [queued]>
[2023-12-22T22:15:28.273+0000] {taskinstance.py:1361} INFO - Starting attempt 1 of 2
[2023-12-22T22:15:28.761+0000] {taskinstance.py:1382} INFO - Executing <Task(GCSObjectExistenceSensor): sense_csv_file> on 2023-12-22 04:00:00+00:00
[2023-12-22T22:15:29.082+0000] {standard_task_runner.py:57} INFO - Started process 229 to run task
[2023-12-22T22:15:29.207+0000] {standard_task_runner.py:84} INFO - Running: ['***', 'tasks', 'run', 'gcs_file_check_dag_2', 'sense_csv_file', 'scheduled__2023-12-22T04:00:00+00:00', '--job-id', '145', '--raw', '--subdir', 'DAGS_FOLDER/dag0002.py', '--cfg-path', '/tmp/tmphj3cy1zn']
[2023-12-22T22:15:29.252+0000] {standard_task_runner.py:85} INFO - Job 145: Subtask sense_csv_file
[2023-12-22T22:15:29.898+0000] {task_command.py:416} INFO - Running <TaskInstance: gcs_file_check_dag_2.sense_csv_file scheduled__2023-12-22T04:00:00+00:00 [running]> on host e1038f319166
[2023-12-22T22:15:48.364+0000] {job.py:219} ERROR - Job heartbeat got an exception
Traceback (most recent call last):
  File "/home/airflow/.local/lib/python3.8/site-packages/sqlalchemy/engine/base.py", line 3371, in _wrap_pool_connect
    return fn()
  File "/home/airflow/.local/lib/python3.8/site-packages/sqlalchemy/pool/base.py", line 327, in connect
    return _ConnectionFairy._checkout(self)
  File "/home/airflow/.local/lib/python3.8/site-packages/sqlalchemy/pool/base.py", line 894, in _checkout
    fairy = _ConnectionRecord.checkout(pool)
  File "/home/airflow/.local/lib/python3.8/site-packages/sqlalchemy/pool/base.py", line 493, in checkout
    rec = pool._do_get()
  File "/home/airflow/.local/lib/python3.8/site-packages/sqlalchemy/pool/impl.py", line 256, in _do_get
    return self._create_connection()
  File "/home/airflow/.local/lib/python3.8/site-packages/sqlalchemy/pool/base.py", line 273, in _create_connection
    return _ConnectionRecord(self)
  File "/home/airflow/.local/lib/python3.8/site-packages/sqlalchemy/pool/base.py", line 388, in __init__
    self.__connect()
  File "/home/airflow/.local/lib/python3.8/site-packages/sqlalchemy/pool/base.py", line 691, in __connect
    pool.logger.debug("Error on connect(): %s", e)
  File "/home/airflow/.local/lib/python3.8/site-packages/sqlalchemy/util/langhelpers.py", line 70, in __exit__
    compat.raise_(
  File "/home/airflow/.local/lib/python3.8/site-packages/sqlalchemy/util/compat.py", line 211, in raise_
    raise exception
  File "/home/airflow/.local/lib/python3.8/site-packages/sqlalchemy/pool/base.py", line 686, in __connect
    self.dbapi_connection = connection = pool._invoke_creator(self)
  File "/home/airflow/.local/lib/python3.8/site-packages/sqlalchemy/engine/create.py", line 574, in connect
    return dialect.connect(*cargs, **cparams)
  File "/home/airflow/.local/lib/python3.8/site-packages/sqlalchemy/engine/default.py", line 598, in connect
    return self.dbapi.connect(*cargs, **cparams)
  File "/home/airflow/.local/lib/python3.8/site-packages/psycopg2/__init__.py", line 122, in connect
    conn = _connect(dsn, connection_factory=connection_factory, **kwasync)
psycopg2.OperationalError: could not translate host name "postgres" to address: Temporary failure in name resolution


The above exception was the direct cause of the following exception:

Traceback (most recent call last):
  File "/home/airflow/.local/lib/python3.8/site-packages/airflow/jobs/job.py", line 190, in heartbeat
    session.merge(self)
  File "/home/airflow/.local/lib/python3.8/site-packages/sqlalchemy/orm/session.py", line 3056, in merge
    return self._merge(
  File "/home/airflow/.local/lib/python3.8/site-packages/sqlalchemy/orm/session.py", line 3136, in _merge
    merged = self.get(
  File "/home/airflow/.local/lib/python3.8/site-packages/sqlalchemy/orm/session.py", line 2853, in get
    return self._get_impl(
  File "/home/airflow/.local/lib/python3.8/site-packages/sqlalchemy/orm/session.py", line 2975, in _get_impl
    return db_load_fn(
  File "/home/airflow/.local/lib/python3.8/site-packages/sqlalchemy/orm/loading.py", line 530, in load_on_pk_identity
    session.execute(
  File "/home/airflow/.local/lib/python3.8/site-packages/sqlalchemy/orm/session.py", line 1716, in execute
    conn = self._connection_for_bind(bind)
  File "/home/airflow/.local/lib/python3.8/site-packages/sqlalchemy/orm/session.py", line 1555, in _connection_for_bind
    return self._transaction._connection_for_bind(
  File "/home/airflow/.local/lib/python3.8/site-packages/sqlalchemy/orm/session.py", line 750, in _connection_for_bind
    conn = bind.connect()
  File "/home/airflow/.local/lib/python3.8/site-packages/sqlalchemy/future/engine.py", line 406, in connect
    return super(Engine, self).connect()
  File "/home/airflow/.local/lib/python3.8/site-packages/sqlalchemy/engine/base.py", line 3325, in connect
    return self._connection_cls(self, close_with_result=close_with_result)
  File "/home/airflow/.local/lib/python3.8/site-packages/sqlalchemy/engine/base.py", line 96, in __init__
    else engine.raw_connection()
  File "/home/airflow/.local/lib/python3.8/site-packages/sqlalchemy/engine/base.py", line 3404, in raw_connection
    return self._wrap_pool_connect(self.pool.connect, _connection)
  File "/home/airflow/.local/lib/python3.8/site-packages/sqlalchemy/engine/base.py", line 3374, in _wrap_pool_connect
    Connection._handle_dbapi_exception_noconnection(
  File "/home/airflow/.local/lib/python3.8/site-packages/sqlalchemy/engine/base.py", line 2208, in _handle_dbapi_exception_noconnection
    util.raise_(
  File "/home/airflow/.local/lib/python3.8/site-packages/sqlalchemy/util/compat.py", line 211, in raise_
    raise exception
  File "/home/airflow/.local/lib/python3.8/site-packages/sqlalchemy/engine/base.py", line 3371, in _wrap_pool_connect
    return fn()
  File "/home/airflow/.local/lib/python3.8/site-packages/sqlalchemy/pool/base.py", line 327, in connect
    return _ConnectionFairy._checkout(self)
  File "/home/airflow/.local/lib/python3.8/site-packages/sqlalchemy/pool/base.py", line 894, in _checkout
    fairy = _ConnectionRecord.checkout(pool)
  File "/home/airflow/.local/lib/python3.8/site-packages/sqlalchemy/pool/base.py", line 493, in checkout
    rec = pool._do_get()
  File "/home/airflow/.local/lib/python3.8/site-packages/sqlalchemy/pool/impl.py", line 256, in _do_get
    return self._create_connection()
  File "/home/airflow/.local/lib/python3.8/site-packages/sqlalchemy/pool/base.py", line 273, in _create_connection
    return _ConnectionRecord(self)
  File "/home/airflow/.local/lib/python3.8/site-packages/sqlalchemy/pool/base.py", line 388, in __init__
    self.__connect()
  File "/home/airflow/.local/lib/python3.8/site-packages/sqlalchemy/pool/base.py", line 691, in __connect
    pool.logger.debug("Error on connect(): %s", e)
  File "/home/airflow/.local/lib/python3.8/site-packages/sqlalchemy/util/langhelpers.py", line 70, in __exit__
    compat.raise_(
  File "/home/airflow/.local/lib/python3.8/site-packages/sqlalchemy/util/compat.py", line 211, in raise_
    raise exception
  File "/home/airflow/.local/lib/python3.8/site-packages/sqlalchemy/pool/base.py", line 686, in __connect
    self.dbapi_connection = connection = pool._invoke_creator(self)
  File "/home/airflow/.local/lib/python3.8/site-packages/sqlalchemy/engine/create.py", line 574, in connect
    return dialect.connect(*cargs, **cparams)
  File "/home/airflow/.local/lib/python3.8/site-packages/sqlalchemy/engine/default.py", line 598, in connect
    return self.dbapi.connect(*cargs, **cparams)
  File "/home/airflow/.local/lib/python3.8/site-packages/psycopg2/__init__.py", line 122, in connect
    conn = _connect(dsn, connection_factory=connection_factory, **kwasync)
sqlalchemy.exc.OperationalError: (psycopg2.OperationalError) could not translate host name "postgres" to address: Temporary failure in name resolution

(Background on this error at: https://sqlalche.me/e/14/e3q8)
[2023-12-22T22:21:05.196+0000] {taskinstance.py:1662} INFO - Exporting env vars: AIRFLOW_CTX_DAG_OWNER='Javad' AIRFLOW_CTX_DAG_ID='gcs_file_check_dag_2' AIRFLOW_CTX_TASK_ID='sense_csv_file' AIRFLOW_CTX_EXECUTION_DATE='2023-12-22T04:00:00+00:00' AIRFLOW_CTX_TRY_NUMBER='1' AIRFLOW_CTX_DAG_RUN_ID='scheduled__2023-12-22T04:00:00+00:00'
[2023-12-22T22:21:43.803+0000] {gcs.py:94} INFO - Sensor checks existence of : avalin-bucket, avalin-bucket/Data/babak1.csv
[2023-12-22T22:19:54.024+0000] {job.py:219} ERROR - Job heartbeat got an exception
Traceback (most recent call last):
  File "/home/airflow/.local/lib/python3.8/site-packages/sqlalchemy/engine/base.py", line 3371, in _wrap_pool_connect
    return fn()
  File "/home/airflow/.local/lib/python3.8/site-packages/sqlalchemy/pool/base.py", line 327, in connect
    return _ConnectionFairy._checkout(self)
  File "/home/airflow/.local/lib/python3.8/site-packages/sqlalchemy/pool/base.py", line 894, in _checkout
    fairy = _ConnectionRecord.checkout(pool)
  File "/home/airflow/.local/lib/python3.8/site-packages/sqlalchemy/pool/base.py", line 493, in checkout
    rec = pool._do_get()
  File "/home/airflow/.local/lib/python3.8/site-packages/sqlalchemy/pool/impl.py", line 256, in _do_get
    return self._create_connection()
  File "/home/airflow/.local/lib/python3.8/site-packages/sqlalchemy/pool/base.py", line 273, in _create_connection
    return _ConnectionRecord(self)
  File "/home/airflow/.local/lib/python3.8/site-packages/sqlalchemy/pool/base.py", line 388, in __init__
    self.__connect()
  File "/home/airflow/.local/lib/python3.8/site-packages/sqlalchemy/pool/base.py", line 691, in __connect
    pool.logger.debug("Error on connect(): %s", e)
  File "/home/airflow/.local/lib/python3.8/site-packages/sqlalchemy/util/langhelpers.py", line 70, in __exit__
    compat.raise_(
  File "/home/airflow/.local/lib/python3.8/site-packages/sqlalchemy/util/compat.py", line 211, in raise_
    raise exception
  File "/home/airflow/.local/lib/python3.8/site-packages/sqlalchemy/pool/base.py", line 686, in __connect
    self.dbapi_connection = connection = pool._invoke_creator(self)
  File "/home/airflow/.local/lib/python3.8/site-packages/sqlalchemy/engine/create.py", line 574, in connect
    return dialect.connect(*cargs, **cparams)
  File "/home/airflow/.local/lib/python3.8/site-packages/sqlalchemy/engine/default.py", line 598, in connect
    return self.dbapi.connect(*cargs, **cparams)
  File "/home/airflow/.local/lib/python3.8/site-packages/psycopg2/__init__.py", line 122, in connect
    conn = _connect(dsn, connection_factory=connection_factory, **kwasync)
psycopg2.OperationalError: could not translate host name "postgres" to address: Temporary failure in name resolution


The above exception was the direct cause of the following exception:

Traceback (most recent call last):
  File "/home/airflow/.local/lib/python3.8/site-packages/airflow/jobs/job.py", line 190, in heartbeat
    session.merge(self)
  File "/home/airflow/.local/lib/python3.8/site-packages/sqlalchemy/orm/session.py", line 3056, in merge
    return self._merge(
  File "/home/airflow/.local/lib/python3.8/site-packages/sqlalchemy/orm/session.py", line 3136, in _merge
    merged = self.get(
  File "/home/airflow/.local/lib/python3.8/site-packages/sqlalchemy/orm/session.py", line 2853, in get
    return self._get_impl(
  File "/home/airflow/.local/lib/python3.8/site-packages/sqlalchemy/orm/session.py", line 2975, in _get_impl
    return db_load_fn(
  File "/home/airflow/.local/lib/python3.8/site-packages/sqlalchemy/orm/loading.py", line 530, in load_on_pk_identity
    session.execute(
  File "/home/airflow/.local/lib/python3.8/site-packages/sqlalchemy/orm/session.py", line 1716, in execute
    conn = self._connection_for_bind(bind)
  File "/home/airflow/.local/lib/python3.8/site-packages/sqlalchemy/orm/session.py", line 1555, in _connection_for_bind
    return self._transaction._connection_for_bind(
  File "/home/airflow/.local/lib/python3.8/site-packages/sqlalchemy/orm/session.py", line 750, in _connection_for_bind
    conn = bind.connect()
  File "/home/airflow/.local/lib/python3.8/site-packages/sqlalchemy/future/engine.py", line 406, in connect
    return super(Engine, self).connect()
  File "/home/airflow/.local/lib/python3.8/site-packages/sqlalchemy/engine/base.py", line 3325, in connect
    return self._connection_cls(self, close_with_result=close_with_result)
  File "/home/airflow/.local/lib/python3.8/site-packages/sqlalchemy/engine/base.py", line 96, in __init__
    else engine.raw_connection()
  File "/home/airflow/.local/lib/python3.8/site-packages/sqlalchemy/engine/base.py", line 3404, in raw_connection
    return self._wrap_pool_connect(self.pool.connect, _connection)
  File "/home/airflow/.local/lib/python3.8/site-packages/sqlalchemy/engine/base.py", line 3374, in _wrap_pool_connect
    Connection._handle_dbapi_exception_noconnection(
  File "/home/airflow/.local/lib/python3.8/site-packages/sqlalchemy/engine/base.py", line 2208, in _handle_dbapi_exception_noconnection
    util.raise_(
  File "/home/airflow/.local/lib/python3.8/site-packages/sqlalchemy/util/compat.py", line 211, in raise_
    raise exception
  File "/home/airflow/.local/lib/python3.8/site-packages/sqlalchemy/engine/base.py", line 3371, in _wrap_pool_connect
    return fn()
  File "/home/airflow/.local/lib/python3.8/site-packages/sqlalchemy/pool/base.py", line 327, in connect
    return _ConnectionFairy._checkout(self)
  File "/home/airflow/.local/lib/python3.8/site-packages/sqlalchemy/pool/base.py", line 894, in _checkout
    fairy = _ConnectionRecord.checkout(pool)
  File "/home/airflow/.local/lib/python3.8/site-packages/sqlalchemy/pool/base.py", line 493, in checkout
    rec = pool._do_get()
  File "/home/airflow/.local/lib/python3.8/site-packages/sqlalchemy/pool/impl.py", line 256, in _do_get
    return self._create_connection()
  File "/home/airflow/.local/lib/python3.8/site-packages/sqlalchemy/pool/base.py", line 273, in _create_connection
    return _ConnectionRecord(self)
  File "/home/airflow/.local/lib/python3.8/site-packages/sqlalchemy/pool/base.py", line 388, in __init__
    self.__connect()
  File "/home/airflow/.local/lib/python3.8/site-packages/sqlalchemy/pool/base.py", line 691, in __connect
    pool.logger.debug("Error on connect(): %s", e)
  File "/home/airflow/.local/lib/python3.8/site-packages/sqlalchemy/util/langhelpers.py", line 70, in __exit__
    compat.raise_(
  File "/home/airflow/.local/lib/python3.8/site-packages/sqlalchemy/util/compat.py", line 211, in raise_
    raise exception
  File "/home/airflow/.local/lib/python3.8/site-packages/sqlalchemy/pool/base.py", line 686, in __connect
    self.dbapi_connection = connection = pool._invoke_creator(self)
  File "/home/airflow/.local/lib/python3.8/site-packages/sqlalchemy/engine/create.py", line 574, in connect
    return dialect.connect(*cargs, **cparams)
  File "/home/airflow/.local/lib/python3.8/site-packages/sqlalchemy/engine/default.py", line 598, in connect
    return self.dbapi.connect(*cargs, **cparams)
  File "/home/airflow/.local/lib/python3.8/site-packages/psycopg2/__init__.py", line 122, in connect
    conn = _connect(dsn, connection_factory=connection_factory, **kwasync)
sqlalchemy.exc.OperationalError: (psycopg2.OperationalError) could not translate host name "postgres" to address: Temporary failure in name resolution

(Background on this error at: https://sqlalche.me/e/14/e3q8)
[2023-12-22T22:23:35.895+0000] {local_task_job_runner.py:205} ERROR - Heartbeat time limit exceeded!
[2023-12-22T22:32:36.364+0000] {process_utils.py:131} INFO - Sending 15 to group 229. PIDs of all processes in the group: [229]
[2023-12-22T22:32:36.363+0000] {process_utils.py:86} INFO - Sending the signal 15 to group 229
[2023-12-22T22:32:37.231+0000] {taskinstance.py:1632} ERROR - Received SIGTERM. Terminating subprocesses.
[2023-12-22T22:32:38.010+0000] {logging_mixin.py:154} WARNING - --- Logging error ---
[2023-12-22T22:32:44.185+0000] {logging_mixin.py:154} WARNING - Traceback (most recent call last):
[2023-12-22T22:32:48.975+0000] {logging_mixin.py:154} WARNING -   File "/home/***/.local/lib/python3.8/site-packages/sqlalchemy/engine/base.py", line 3371, in _wrap_pool_connect
    return fn()
[2023-12-22T22:32:48.994+0000] {logging_mixin.py:154} WARNING -   File "/home/***/.local/lib/python3.8/site-packages/sqlalchemy/pool/base.py", line 327, in connect
    return _ConnectionFairy._checkout(self)
[2023-12-22T22:32:48.999+0000] {logging_mixin.py:154} WARNING -   File "/home/***/.local/lib/python3.8/site-packages/sqlalchemy/pool/base.py", line 894, in _checkout
    fairy = _ConnectionRecord.checkout(pool)
[2023-12-22T22:32:49.005+0000] {logging_mixin.py:154} WARNING -   File "/home/***/.local/lib/python3.8/site-packages/sqlalchemy/pool/base.py", line 493, in checkout
    rec = pool._do_get()
[2023-12-22T22:32:49.013+0000] {logging_mixin.py:154} WARNING -   File "/home/***/.local/lib/python3.8/site-packages/sqlalchemy/pool/impl.py", line 256, in _do_get
    return self._create_connection()
[2023-12-22T22:32:49.018+0000] {logging_mixin.py:154} WARNING -   File "/home/***/.local/lib/python3.8/site-packages/sqlalchemy/pool/base.py", line 273, in _create_connection
    return _ConnectionRecord(self)
[2023-12-22T22:32:49.022+0000] {logging_mixin.py:154} WARNING -   File "/home/***/.local/lib/python3.8/site-packages/sqlalchemy/pool/base.py", line 388, in __init__
    self.__connect()
[2023-12-22T22:32:49.342+0000] {logging_mixin.py:154} WARNING -   File "/home/***/.local/lib/python3.8/site-packages/sqlalchemy/pool/base.py", line 691, in __connect
    pool.logger.debug("Error on connect(): %s", e)
[2023-12-22T22:32:49.352+0000] {logging_mixin.py:154} WARNING -   File "/home/***/.local/lib/python3.8/site-packages/sqlalchemy/util/langhelpers.py", line 70, in __exit__
    compat.raise_(
[2023-12-22T22:32:49.356+0000] {logging_mixin.py:154} WARNING -   File "/home/***/.local/lib/python3.8/site-packages/sqlalchemy/util/compat.py", line 211, in raise_
    raise exception
[2023-12-22T22:32:49.362+0000] {logging_mixin.py:154} WARNING -   File "/home/***/.local/lib/python3.8/site-packages/sqlalchemy/pool/base.py", line 686, in __connect
    self.dbapi_connection = connection = pool._invoke_creator(self)
[2023-12-22T22:32:50.327+0000] {logging_mixin.py:154} WARNING -   File "/home/***/.local/lib/python3.8/site-packages/sqlalchemy/engine/create.py", line 574, in connect
    return dialect.connect(*cargs, **cparams)
[2023-12-22T22:32:50.406+0000] {logging_mixin.py:154} WARNING -   File "/home/***/.local/lib/python3.8/site-packages/sqlalchemy/engine/default.py", line 598, in connect
    return self.dbapi.connect(*cargs, **cparams)
[2023-12-22T22:32:50.423+0000] {logging_mixin.py:154} WARNING -   File "/home/***/.local/lib/python3.8/site-packages/psycopg2/__init__.py", line 122, in connect
    conn = _connect(dsn, connection_factory=connection_factory, **kwasync)
[2023-12-22T22:32:50.431+0000] {logging_mixin.py:154} WARNING - psycopg2.OperationalError: could not translate host name "postgres" to address: Temporary failure in name resolution
[2023-12-22T22:32:50.743+0000] {logging_mixin.py:154} WARNING - 
The above exception was the direct cause of the following exception:
[2023-12-22T22:32:51.202+0000] {logging_mixin.py:154} WARNING - Traceback (most recent call last):
[2023-12-22T22:32:51.235+0000] {logging_mixin.py:154} WARNING -   File "/home/***/.local/lib/python3.8/site-packages/***/models/connection.py", line 466, in get_connection_from_secrets
    conn = secrets_backend.get_connection(conn_id=conn_id)
[2023-12-22T22:32:51.304+0000] {logging_mixin.py:154} WARNING -   File "/home/***/.local/lib/python3.8/site-packages/***/utils/session.py", line 79, in wrapper
    return func(*args, session=session, **kwargs)
[2023-12-22T22:32:51.704+0000] {logging_mixin.py:154} WARNING -   File "/home/***/.local/lib/python3.8/site-packages/***/secrets/metastore.py", line 42, in get_connection
    conn = session.scalar(select(Connection).where(Connection.conn_id == conn_id).limit(1))
[2023-12-22T22:32:51.814+0000] {logging_mixin.py:154} WARNING -   File "/home/***/.local/lib/python3.8/site-packages/sqlalchemy/orm/session.py", line 1747, in scalar
    return self.execute(
[2023-12-22T22:32:51.922+0000] {logging_mixin.py:154} WARNING -   File "/home/***/.local/lib/python3.8/site-packages/sqlalchemy/orm/session.py", line 1716, in execute
    conn = self._connection_for_bind(bind)
[2023-12-22T22:32:51.983+0000] {logging_mixin.py:154} WARNING -   File "/home/***/.local/lib/python3.8/site-packages/sqlalchemy/orm/session.py", line 1555, in _connection_for_bind
    return self._transaction._connection_for_bind(
[2023-12-22T22:32:52.112+0000] {logging_mixin.py:154} WARNING -   File "/home/***/.local/lib/python3.8/site-packages/sqlalchemy/orm/session.py", line 750, in _connection_for_bind
    conn = bind.connect()
[2023-12-22T22:32:52.119+0000] {logging_mixin.py:154} WARNING -   File "/home/***/.local/lib/python3.8/site-packages/sqlalchemy/future/engine.py", line 406, in connect
    return super(Engine, self).connect()
[2023-12-22T22:32:52.122+0000] {logging_mixin.py:154} WARNING -   File "/home/***/.local/lib/python3.8/site-packages/sqlalchemy/engine/base.py", line 3325, in connect
    return self._connection_cls(self, close_with_result=close_with_result)
[2023-12-22T22:32:52.128+0000] {logging_mixin.py:154} WARNING -   File "/home/***/.local/lib/python3.8/site-packages/sqlalchemy/engine/base.py", line 96, in __init__
    else engine.raw_connection()
[2023-12-22T22:32:52.134+0000] {logging_mixin.py:154} WARNING -   File "/home/***/.local/lib/python3.8/site-packages/sqlalchemy/engine/base.py", line 3404, in raw_connection
    return self._wrap_pool_connect(self.pool.connect, _connection)
[2023-12-22T22:32:52.169+0000] {logging_mixin.py:154} WARNING -   File "/home/***/.local/lib/python3.8/site-packages/sqlalchemy/engine/base.py", line 3374, in _wrap_pool_connect
    Connection._handle_dbapi_exception_noconnection(
[2023-12-22T22:32:52.619+0000] {logging_mixin.py:154} WARNING -   File "/home/***/.local/lib/python3.8/site-packages/sqlalchemy/engine/base.py", line 2208, in _handle_dbapi_exception_noconnection
    util.raise_(
[2023-12-22T22:32:52.652+0000] {logging_mixin.py:154} WARNING -   File "/home/***/.local/lib/python3.8/site-packages/sqlalchemy/util/compat.py", line 211, in raise_
    raise exception
[2023-12-22T22:32:52.666+0000] {logging_mixin.py:154} WARNING -   File "/home/***/.local/lib/python3.8/site-packages/sqlalchemy/engine/base.py", line 3371, in _wrap_pool_connect
    return fn()
[2023-12-22T22:32:52.741+0000] {logging_mixin.py:154} WARNING -   File "/home/***/.local/lib/python3.8/site-packages/sqlalchemy/pool/base.py", line 327, in connect
    return _ConnectionFairy._checkout(self)
[2023-12-22T22:32:52.746+0000] {logging_mixin.py:154} WARNING -   File "/home/***/.local/lib/python3.8/site-packages/sqlalchemy/pool/base.py", line 894, in _checkout
    fairy = _ConnectionRecord.checkout(pool)
[2023-12-22T22:32:52.772+0000] {logging_mixin.py:154} WARNING -   File "/home/***/.local/lib/python3.8/site-packages/sqlalchemy/pool/base.py", line 493, in checkout
    rec = pool._do_get()
[2023-12-22T22:32:52.793+0000] {logging_mixin.py:154} WARNING -   File "/home/***/.local/lib/python3.8/site-packages/sqlalchemy/pool/impl.py", line 256, in _do_get
    return self._create_connection()
[2023-12-22T22:32:52.795+0000] {logging_mixin.py:154} WARNING -   File "/home/***/.local/lib/python3.8/site-packages/sqlalchemy/pool/base.py", line 273, in _create_connection
    return _ConnectionRecord(self)
[2023-12-22T22:32:52.798+0000] {logging_mixin.py:154} WARNING -   File "/home/***/.local/lib/python3.8/site-packages/sqlalchemy/pool/base.py", line 388, in __init__
    self.__connect()
[2023-12-22T22:32:52.833+0000] {logging_mixin.py:154} WARNING -   File "/home/***/.local/lib/python3.8/site-packages/sqlalchemy/pool/base.py", line 691, in __connect
    pool.logger.debug("Error on connect(): %s", e)
[2023-12-22T22:32:52.836+0000] {logging_mixin.py:154} WARNING -   File "/home/***/.local/lib/python3.8/site-packages/sqlalchemy/util/langhelpers.py", line 70, in __exit__
    compat.raise_(
[2023-12-22T22:32:52.847+0000] {logging_mixin.py:154} WARNING -   File "/home/***/.local/lib/python3.8/site-packages/sqlalchemy/util/compat.py", line 211, in raise_
    raise exception
[2023-12-22T22:32:52.857+0000] {logging_mixin.py:154} WARNING -   File "/home/***/.local/lib/python3.8/site-packages/sqlalchemy/pool/base.py", line 686, in __connect
    self.dbapi_connection = connection = pool._invoke_creator(self)
[2023-12-22T22:32:52.881+0000] {logging_mixin.py:154} WARNING -   File "/home/***/.local/lib/python3.8/site-packages/sqlalchemy/engine/create.py", line 574, in connect
    return dialect.connect(*cargs, **cparams)
[2023-12-22T22:32:52.906+0000] {logging_mixin.py:154} WARNING -   File "/home/***/.local/lib/python3.8/site-packages/sqlalchemy/engine/default.py", line 598, in connect
    return self.dbapi.connect(*cargs, **cparams)
[2023-12-22T22:32:52.919+0000] {logging_mixin.py:154} WARNING -   File "/home/***/.local/lib/python3.8/site-packages/psycopg2/__init__.py", line 122, in connect
    conn = _connect(dsn, connection_factory=connection_factory, **kwasync)
[2023-12-22T22:32:52.932+0000] {logging_mixin.py:154} WARNING - sqlalchemy.exc.OperationalError: (psycopg2.OperationalError) could not translate host name "postgres" to address: Temporary failure in name resolution

(Background on this error at: https://sqlalche.me/e/14/e3q8)
[2023-12-22T22:32:52.937+0000] {logging_mixin.py:154} WARNING - 
During handling of the above exception, another exception occurred:
[2023-12-22T22:32:52.941+0000] {logging_mixin.py:154} WARNING - Traceback (most recent call last):
[2023-12-22T22:32:52.949+0000] {logging_mixin.py:154} WARNING -   File "/usr/local/lib/python3.8/logging/__init__.py", line 1085, in emit
    msg = self.format(record)
[2023-12-22T22:32:52.998+0000] {logging_mixin.py:154} WARNING -   File "/usr/local/lib/python3.8/logging/__init__.py", line 929, in format
    return fmt.format(record)
[2023-12-22T22:32:53.008+0000] {logging_mixin.py:154} WARNING -   File "/usr/local/lib/python3.8/logging/__init__.py", line 676, in format
    record.exc_text = self.formatException(record.exc_info)
[2023-12-22T22:32:53.019+0000] {logging_mixin.py:154} WARNING -   File "/usr/local/lib/python3.8/logging/__init__.py", line 626, in formatException
    traceback.print_exception(ei[0], ei[1], tb, None, sio)
[2023-12-22T22:32:53.029+0000] {logging_mixin.py:154} WARNING -   File "/usr/local/lib/python3.8/traceback.py", line 103, in print_exception
    for line in TracebackException(
[2023-12-22T22:32:53.035+0000] {logging_mixin.py:154} WARNING -   File "/home/***/.local/lib/python3.8/site-packages/exceptiongroup/_formatting.py", line 96, in __init__
    self.stack = traceback.StackSummary.extract(
[2023-12-22T22:32:53.045+0000] {logging_mixin.py:154} WARNING -   File "/usr/local/lib/python3.8/traceback.py", line 366, in extract
    f.line
[2023-12-22T22:32:53.053+0000] {logging_mixin.py:154} WARNING -   File "/usr/local/lib/python3.8/traceback.py", line 288, in line
    self._line = linecache.getline(self.filename, self.lineno).strip()
[2023-12-22T22:32:53.058+0000] {logging_mixin.py:154} WARNING -   File "/usr/local/lib/python3.8/linecache.py", line 16, in getline
    lines = getlines(filename, module_globals)
[2023-12-22T22:32:53.096+0000] {logging_mixin.py:154} WARNING -   File "/usr/local/lib/python3.8/linecache.py", line 47, in getlines
    return updatecache(filename, module_globals)
[2023-12-22T22:32:53.183+0000] {logging_mixin.py:154} WARNING -   File "/usr/local/lib/python3.8/linecache.py", line 137, in updatecache
    lines = fp.readlines()
[2023-12-22T22:32:53.193+0000] {logging_mixin.py:154} WARNING -   File "/usr/local/lib/python3.8/codecs.py", line 319, in decode
    def decode(self, input, final=False):
[2023-12-22T22:32:53.202+0000] {logging_mixin.py:154} WARNING -   File "/home/***/.local/lib/python3.8/site-packages/***/models/taskinstance.py", line 1634, in signal_handler
    raise AirflowException("Task received SIGTERM signal")
[2023-12-22T22:32:53.222+0000] {logging_mixin.py:154} WARNING - ***.exceptions.AirflowException: Task received SIGTERM signal
[2023-12-22T22:32:53.276+0000] {logging_mixin.py:154} WARNING - Call stack:
[2023-12-22T22:32:53.439+0000] {logging_mixin.py:154} WARNING -   File "/home/***/.local/bin/***", line 8, in <module>
    sys.exit(main())
[2023-12-22T22:32:53.445+0000] {logging_mixin.py:154} WARNING -   File "/home/***/.local/lib/python3.8/site-packages/***/__main__.py", line 57, in main
    args.func(args)
[2023-12-22T22:32:53.453+0000] {logging_mixin.py:154} WARNING -   File "/home/***/.local/lib/python3.8/site-packages/***/cli/cli_config.py", line 49, in command
    return func(*args, **kwargs)
[2023-12-22T22:32:53.513+0000] {logging_mixin.py:154} WARNING -   File "/home/***/.local/lib/python3.8/site-packages/***/utils/cli.py", line 114, in wrapper
    return f(*args, **kwargs)
[2023-12-22T22:32:53.521+0000] {logging_mixin.py:154} WARNING -   File "/home/***/.local/lib/python3.8/site-packages/***/utils/providers_configuration_loader.py", line 55, in wrapped_function
    return func(*args, **kwargs)
[2023-12-22T22:32:53.573+0000] {logging_mixin.py:154} WARNING -   File "/home/***/.local/lib/python3.8/site-packages/***/cli/commands/celery_command.py", line 242, in worker
    celery_app.worker_main(options)
[2023-12-22T22:32:53.630+0000] {logging_mixin.py:154} WARNING -   File "/home/***/.local/lib/python3.8/site-packages/celery/app/base.py", line 388, in worker_main
    self.start(argv=argv)
[2023-12-22T22:32:53.669+0000] {logging_mixin.py:154} WARNING -   File "/home/***/.local/lib/python3.8/site-packages/celery/app/base.py", line 368, in start
    celery.main(args=argv, standalone_mode=False)
[2023-12-22T22:32:53.686+0000] {logging_mixin.py:154} WARNING -   File "/home/***/.local/lib/python3.8/site-packages/click/core.py", line 1078, in main
    rv = self.invoke(ctx)
[2023-12-22T22:32:53.706+0000] {logging_mixin.py:154} WARNING -   File "/home/***/.local/lib/python3.8/site-packages/click/core.py", line 1688, in invoke
    return _process_result(sub_ctx.command.invoke(sub_ctx))
[2023-12-22T22:32:53.812+0000] {logging_mixin.py:154} WARNING -   File "/home/***/.local/lib/python3.8/site-packages/click/core.py", line 1434, in invoke
    return ctx.invoke(self.callback, **ctx.params)
[2023-12-22T22:32:53.822+0000] {logging_mixin.py:154} WARNING -   File "/home/***/.local/lib/python3.8/site-packages/click/core.py", line 783, in invoke
    return __callback(*args, **kwargs)
[2023-12-22T22:32:53.881+0000] {logging_mixin.py:154} WARNING -   File "/home/***/.local/lib/python3.8/site-packages/click/decorators.py", line 33, in new_func
    return f(get_current_context(), *args, **kwargs)
[2023-12-22T22:32:53.905+0000] {logging_mixin.py:154} WARNING -   File "/home/***/.local/lib/python3.8/site-packages/celery/bin/base.py", line 134, in caller
    return f(ctx, *args, **kwargs)
[2023-12-22T22:32:53.912+0000] {logging_mixin.py:154} WARNING -   File "/home/***/.local/lib/python3.8/site-packages/celery/bin/worker.py", line 356, in worker
    worker.start()
[2023-12-22T22:32:53.921+0000] {logging_mixin.py:154} WARNING -   File "/home/***/.local/lib/python3.8/site-packages/celery/worker/worker.py", line 202, in start
    self.blueprint.start(self)
[2023-12-22T22:32:53.925+0000] {logging_mixin.py:154} WARNING -   File "/home/***/.local/lib/python3.8/site-packages/celery/bootsteps.py", line 116, in start
    step.start(parent)
[2023-12-22T22:32:53.928+0000] {logging_mixin.py:154} WARNING -   File "/home/***/.local/lib/python3.8/site-packages/celery/bootsteps.py", line 365, in start
    return self.obj.start()
[2023-12-22T22:32:53.930+0000] {logging_mixin.py:154} WARNING -   File "/home/***/.local/lib/python3.8/site-packages/celery/concurrency/base.py", line 130, in start
    self.on_start()
[2023-12-22T22:32:53.936+0000] {logging_mixin.py:154} WARNING -   File "/home/***/.local/lib/python3.8/site-packages/celery/concurrency/prefork.py", line 109, in on_start
    P = self._pool = Pool(processes=self.limit,
[2023-12-22T22:32:53.939+0000] {logging_mixin.py:154} WARNING -   File "/home/***/.local/lib/python3.8/site-packages/celery/concurrency/asynpool.py", line 464, in __init__
    super().__init__(processes, *args, **kwargs)
[2023-12-22T22:32:53.942+0000] {logging_mixin.py:154} WARNING -   File "/home/***/.local/lib/python3.8/site-packages/billiard/pool.py", line 1045, in __init__
    self._create_worker_process(i)
[2023-12-22T22:32:53.950+0000] {logging_mixin.py:154} WARNING -   File "/home/***/.local/lib/python3.8/site-packages/celery/concurrency/asynpool.py", line 482, in _create_worker_process
    return super()._create_worker_process(i)
[2023-12-22T22:32:53.967+0000] {logging_mixin.py:154} WARNING -   File "/home/***/.local/lib/python3.8/site-packages/billiard/pool.py", line 1157, in _create_worker_process
    w.start()
[2023-12-22T22:32:53.968+0000] {logging_mixin.py:154} WARNING -   File "/home/***/.local/lib/python3.8/site-packages/billiard/process.py", line 120, in start
    self._popen = self._Popen(self)
[2023-12-22T22:32:53.969+0000] {logging_mixin.py:154} WARNING -   File "/home/***/.local/lib/python3.8/site-packages/billiard/context.py", line 331, in _Popen
    return Popen(process_obj)
[2023-12-22T22:32:53.971+0000] {logging_mixin.py:154} WARNING -   File "/home/***/.local/lib/python3.8/site-packages/billiard/popen_fork.py", line 22, in __init__
    self._launch(process_obj)
[2023-12-22T22:32:53.974+0000] {logging_mixin.py:154} WARNING -   File "/home/***/.local/lib/python3.8/site-packages/billiard/popen_fork.py", line 77, in _launch
    code = process_obj._bootstrap()
[2023-12-22T22:32:53.975+0000] {logging_mixin.py:154} WARNING -   File "/home/***/.local/lib/python3.8/site-packages/billiard/process.py", line 323, in _bootstrap
    self.run()
[2023-12-22T22:32:53.976+0000] {logging_mixin.py:154} WARNING -   File "/home/***/.local/lib/python3.8/site-packages/billiard/process.py", line 110, in run
    self._target(*self._args, **self._kwargs)
[2023-12-22T22:32:53.977+0000] {logging_mixin.py:154} WARNING -   File "/home/***/.local/lib/python3.8/site-packages/billiard/pool.py", line 291, in __call__
    sys.exit(self.workloop(pid=pid))
[2023-12-22T22:32:53.980+0000] {logging_mixin.py:154} WARNING -   File "/home/***/.local/lib/python3.8/site-packages/billiard/pool.py", line 361, in workloop
    result = (True, prepare_result(fun(*args, **kwargs)))
[2023-12-22T22:32:53.981+0000] {logging_mixin.py:154} WARNING -   File "/home/***/.local/lib/python3.8/site-packages/celery/app/trace.py", line 675, in fast_trace_task
    R, I, T, Rstr = tasks[task].__trace__(
[2023-12-22T22:32:53.983+0000] {logging_mixin.py:154} WARNING -   File "/home/***/.local/lib/python3.8/site-packages/celery/app/trace.py", line 477, in trace_task
    R = retval = fun(*args, **kwargs)
[2023-12-22T22:32:53.986+0000] {logging_mixin.py:154} WARNING -   File "/home/***/.local/lib/python3.8/site-packages/celery/app/trace.py", line 760, in __protected_call__
    return self.run(*args, **kwargs)
[2023-12-22T22:32:53.987+0000] {logging_mixin.py:154} WARNING -   File "/home/***/.local/lib/python3.8/site-packages/***/providers/celery/executors/celery_executor_utils.py", line 134, in execute_command
    _execute_in_fork(command_to_exec, celery_task_id)
[2023-12-22T22:32:53.989+0000] {logging_mixin.py:154} WARNING -   File "/home/***/.local/lib/python3.8/site-packages/***/providers/celery/executors/celery_executor_utils.py", line 168, in _execute_in_fork
    args.func(args)
[2023-12-22T22:32:53.990+0000] {logging_mixin.py:154} WARNING -   File "/home/***/.local/lib/python3.8/site-packages/***/cli/cli_config.py", line 49, in command
    return func(*args, **kwargs)
[2023-12-22T22:32:53.991+0000] {logging_mixin.py:154} WARNING -   File "/home/***/.local/lib/python3.8/site-packages/***/utils/cli.py", line 114, in wrapper
    return f(*args, **kwargs)
[2023-12-22T22:32:53.992+0000] {logging_mixin.py:154} WARNING -   File "/home/***/.local/lib/python3.8/site-packages/***/cli/commands/task_command.py", line 431, in task_run
    task_return_code = _run_task_by_selected_method(args, _dag, ti)
[2023-12-22T22:32:53.993+0000] {logging_mixin.py:154} WARNING -   File "/home/***/.local/lib/python3.8/site-packages/***/cli/commands/task_command.py", line 209, in _run_task_by_selected_method
    return _run_task_by_local_task_job(args, ti)
[2023-12-22T22:32:53.999+0000] {logging_mixin.py:154} WARNING -   File "/home/***/.local/lib/python3.8/site-packages/***/cli/commands/task_command.py", line 271, in _run_task_by_local_task_job
    ret = run_job(job=job_runner.job, execute_callable=job_runner._execute)
[2023-12-22T22:32:54.002+0000] {logging_mixin.py:154} WARNING -   File "/home/***/.local/lib/python3.8/site-packages/***/utils/session.py", line 79, in wrapper
    return func(*args, session=session, **kwargs)
[2023-12-22T22:32:54.005+0000] {logging_mixin.py:154} WARNING -   File "/home/***/.local/lib/python3.8/site-packages/***/jobs/job.py", line 289, in run_job
    return execute_job(job, execute_callable=execute_callable)
[2023-12-22T22:32:54.007+0000] {logging_mixin.py:154} WARNING -   File "/home/***/.local/lib/python3.8/site-packages/***/jobs/job.py", line 318, in execute_job
    ret = execute_callable()
[2023-12-22T22:32:54.009+0000] {logging_mixin.py:154} WARNING -   File "/home/***/.local/lib/python3.8/site-packages/***/jobs/local_task_job_runner.py", line 159, in _execute
    self.task_runner.start()
[2023-12-22T22:32:54.010+0000] {logging_mixin.py:154} WARNING -   File "/home/***/.local/lib/python3.8/site-packages/***/task/task_runner/standard_task_runner.py", line 45, in start
    self.process = self._start_by_fork()
[2023-12-22T22:32:54.012+0000] {logging_mixin.py:154} WARNING -   File "/home/***/.local/lib/python3.8/site-packages/***/task/task_runner/standard_task_runner.py", line 97, in _start_by_fork
    ret = args.func(args, dag=self.dag)
[2023-12-22T22:32:54.014+0000] {logging_mixin.py:154} WARNING -   File "/home/***/.local/lib/python3.8/site-packages/***/cli/cli_config.py", line 49, in command
    return func(*args, **kwargs)
[2023-12-22T22:32:54.015+0000] {logging_mixin.py:154} WARNING -   File "/home/***/.local/lib/python3.8/site-packages/***/utils/cli.py", line 114, in wrapper
    return f(*args, **kwargs)
[2023-12-22T22:32:54.017+0000] {logging_mixin.py:154} WARNING -   File "/home/***/.local/lib/python3.8/site-packages/***/cli/commands/task_command.py", line 431, in task_run
    task_return_code = _run_task_by_selected_method(args, _dag, ti)
[2023-12-22T22:32:54.018+0000] {logging_mixin.py:154} WARNING -   File "/home/***/.local/lib/python3.8/site-packages/***/cli/commands/task_command.py", line 211, in _run_task_by_selected_method
    return _run_raw_task(args, ti)
[2023-12-22T22:32:54.019+0000] {logging_mixin.py:154} WARNING -   File "/home/***/.local/lib/python3.8/site-packages/***/cli/commands/task_command.py", line 290, in _run_raw_task
    return ti._run_raw_task(
[2023-12-22T22:32:54.022+0000] {logging_mixin.py:154} WARNING -   File "/home/***/.local/lib/python3.8/site-packages/***/utils/session.py", line 79, in wrapper
    return func(*args, session=session, **kwargs)
[2023-12-22T22:32:54.024+0000] {logging_mixin.py:154} WARNING -   File "/home/***/.local/lib/python3.8/site-packages/***/models/taskinstance.py", line 1518, in _run_raw_task
    self._execute_task_with_callbacks(context, test_mode, session=session)
[2023-12-22T22:32:54.028+0000] {logging_mixin.py:154} WARNING -   File "/home/***/.local/lib/python3.8/site-packages/***/models/taskinstance.py", line 1681, in _execute_task_with_callbacks
    result = self._execute_task(context, task_orig)
[2023-12-22T22:32:54.030+0000] {logging_mixin.py:154} WARNING -   File "/home/***/.local/lib/python3.8/site-packages/***/models/taskinstance.py", line 1744, in _execute_task
    result = execute_callable(context=context, **execute_callable_kwargs)
[2023-12-22T22:32:54.032+0000] {logging_mixin.py:154} WARNING -   File "/home/***/.local/lib/python3.8/site-packages/***/providers/google/cloud/sensors/gcs.py", line 104, in execute
    super().execute(context)
[2023-12-22T22:32:54.035+0000] {logging_mixin.py:154} WARNING -   File "/home/***/.local/lib/python3.8/site-packages/***/sensors/base.py", line 239, in execute
    poke_return = self.poke(context)
[2023-12-22T22:32:54.042+0000] {logging_mixin.py:154} WARNING -   File "/home/***/.local/lib/python3.8/site-packages/***/providers/google/cloud/sensors/gcs.py", line 95, in poke
    hook = GCSHook(
[2023-12-22T22:32:54.044+0000] {logging_mixin.py:154} WARNING -   File "/home/***/.local/lib/python3.8/site-packages/***/providers/google/cloud/hooks/gcs.py", line 164, in __init__
    super().__init__(
[2023-12-22T22:32:54.046+0000] {logging_mixin.py:154} WARNING -   File "/home/***/.local/lib/python3.8/site-packages/***/providers/google/common/hooks/base_google.py", line 242, in __init__
    self.extras: dict = self.get_connection(self.gcp_conn_id).extra_dejson
[2023-12-22T22:32:54.059+0000] {logging_mixin.py:154} WARNING -   File "/home/***/.local/lib/python3.8/site-packages/***/hooks/base.py", line 72, in get_connection
    conn = Connection.get_connection_from_secrets(conn_id)
[2023-12-22T22:32:54.062+0000] {logging_mixin.py:154} WARNING -   File "/home/***/.local/lib/python3.8/site-packages/***/models/connection.py", line 471, in get_connection_from_secrets
    log.exception(
[2023-12-22T22:32:54.065+0000] {logging_mixin.py:154} WARNING -   File "/usr/local/lib/python3.8/logging/__init__.py", line 1481, in exception
    self.error(msg, *args, exc_info=exc_info, **kwargs)
[2023-12-22T22:32:54.067+0000] {logging_mixin.py:154} WARNING -   File "/usr/local/lib/python3.8/logging/__init__.py", line 1475, in error
    self._log(ERROR, msg, args, **kwargs)
[2023-12-22T22:32:54.068+0000] {logging_mixin.py:154} WARNING -   File "/usr/local/lib/python3.8/logging/__init__.py", line 1589, in _log
    self.handle(record)
[2023-12-22T22:32:54.074+0000] {logging_mixin.py:154} WARNING -   File "/usr/local/lib/python3.8/logging/__init__.py", line 1599, in handle
    self.callHandlers(record)
[2023-12-22T22:32:54.075+0000] {logging_mixin.py:154} WARNING -   File "/usr/local/lib/python3.8/logging/__init__.py", line 1661, in callHandlers
    hdlr.handle(record)
[2023-12-22T22:32:54.077+0000] {logging_mixin.py:154} WARNING -   File "/usr/local/lib/python3.8/logging/__init__.py", line 954, in handle
    self.emit(record)
[2023-12-22T22:32:54.080+0000] {logging_mixin.py:154} WARNING -   File "/home/***/.local/lib/python3.8/site-packages/***/utils/log/file_task_handler.py", line 210, in emit
    self.handler.emit(record)
[2023-12-22T22:32:54.084+0000] {logging_mixin.py:154} WARNING - Message: 'Unable to retrieve connection from secrets backend (%s). Checking subsequent secrets backend.'
Arguments: ('MetastoreBackend',)
[2023-12-22T22:32:54.107+0000] {taskinstance.py:1542} INFO - Skipping due to soft_fail is set to True.
[2023-12-22T22:32:54.379+0000] {taskinstance.py:1400} INFO - Marking task as SKIPPED. dag_id=gcs_file_check_dag_2, task_id=sense_csv_file, execution_date=20231222T040000, start_date=20231222T221527, end_date=20231222T223254
[2023-12-22T22:32:55.020+0000] {process_utils.py:79} INFO - Process psutil.Process(pid=229, status='terminated', exitcode=0, started='22:15:28') (229) terminated with exit code 0
